# Define function foo(x)
def foo(x):
    # Assert statement
    assert x
    # If assert passes, the function returns 1/x
    return 1/x

try:
    # Call foo with 0 
    print(foo(0))

except ZeroDivisionError:
    # Catch a ZeroDivisionError if foo attempts to divide by zero
    print("zero")

"""
The output of the code is:
Traceback (most recent call last):
  File "script.py", line 9, in <module>
    print(foo(0))
  File "script.py", line 2, in foo
    assert x
AssertionError

An AssertionError will be raised when foo(0) is called, and it will not be caught by the except block. 
As a result, the program will terminate and print an AssertionError traceback.
"""

